<?xml version="1.0"?>
<robot xmlns:xacro="http://www.ros.org/wiki/xacro" name="my_robot">

    <!-- PROPERTIES -->
    <xacro:property name="chassis_length" value="0.25"/>
    <xacro:property name="chassis_width" value="0.22"/>
    <xacro:property name="chassis_height" value="0.10"/>
    <xacro:property name="chassis_mass" value="1.0"/>
    
    <xacro:property name="wheel_radius" value="0.0325"/>
    <xacro:property name="wheel_thickness" value="0.02"/>
    <xacro:property name="wheel_mass" value="0.1"/>
    <xacro:property name="wheel_offset_x" value="0.0"/>
    <xacro:property name="wheel_offset_y" value="${chassis_width/2 + wheel_thickness/2}"/> 
    <xacro:property name="wheel_separation" value="0.22"/>
    
    <xacro:property name="caster_radius" value="0.0325"/>
    <xacro:property name="caster_mass" value="0.1"/>
    <xacro:property name="caster_offset_x" value="0.1"/>

    <!-- NEW LIDAR PROPERTIES -->
    <xacro:property name="lidar_radius" value="0.035"/> <!-- Approx A1 Size -->
    <xacro:property name="lidar_height" value="0.04"/>
    <xacro:property name="lidar_mass" value="0.17"/>

    <!-- MATERIALS -->
    <material name="blue">
        <color rgba="0.2 0.2 1 1"/>
    </material>
    <material name="black">
        <color rgba="0 0 0 1"/>
    </material>
    <material name="white">
        <color rgba="1 1 1 1"/>
    </material>
    <!-- Added Red for Lidar -->
    <material name="red">
        <color rgba="1 0 0 1"/>
    </material>

    <!-- INERTIAL MACROS -->
    <xacro:macro name="box_inertia" params="mass x y z">
        <inertial>
            <mass value="${mass}"/>
            <inertia ixx="${(1/12) * mass * (y*y+z*z)}" ixy="0.0" ixz="0.0"
                     iyy="${(1/12) * mass * (x*x+z*z)}" iyz="0.0"
                     izz="${(1/12) * mass * (x*x+y*y)}"/>
        </inertial>
    </xacro:macro>

    <xacro:macro name="cylinder_inertia" params="mass r h">
        <inertial>
            <mass value="${mass}"/>
            <inertia ixx="${(1/12) * mass * (3*r*r + h*h)}" ixy="0" ixz="0"
                     iyy="${(1/12) * mass * (3*r*r + h*h)}" iyz="0"
                     izz="${(1/2) * mass * (r*r)}"/>
        </inertial>
    </xacro:macro>

    <xacro:macro name="sphere_inertia" params="mass r">
        <inertial>
            <mass value="${mass}"/>
            <inertia ixx="${(2/5) * mass * (r*r)}" ixy="0.0" ixz="0.0"
                     iyy="${(2/5) * mass * (r*r)}" iyz="0.0"
                     izz="${(2/5) * mass * (r*r)}"/>
        </inertial>
    </xacro:macro>

    <!-- BASE LINK (Virtual) -->
    <link name="base_footprint">
    </link>

    <!-- CHASSIS LINK -->
    <joint name="base_link_joint" type="fixed">
        <parent link="base_footprint"/>
        <child link="base_link"/>
        <origin xyz="${-wheel_offset_x} 0 0"/>
    </joint>

    <link name="base_link">
        <visual>
            <origin xyz="${chassis_length/2} 0 ${chassis_height/2}"/>
            <geometry>
                <box size="${chassis_length} ${chassis_width} ${chassis_height}"/>
            </geometry>
            <material name="blue"/>
        </visual>
        <collision>
            <origin xyz="${chassis_length/2} 0 ${chassis_height/2}"/>
            <geometry>
                <box size="${chassis_length} ${chassis_width} ${chassis_height}"/>
            </geometry>
        </collision>
        <xacro:box_inertia mass="${chassis_mass}" x="${chassis_length}" y="${chassis_width}" z="${chassis_height}"/>
    </link>

    <!-- WHEEL MACRO -->
    <xacro:macro name="wheel" params="prefix y_reflect">
        <link name="${prefix}_wheel">
            <visual>
                <origin xyz="0 0 0" rpy="${pi/2} 0 0"/>
                <geometry>
                    <cylinder radius="${wheel_radius}" length="${wheel_thickness}"/>
                </geometry>
                <material name="black"/>
            </visual>
            <collision>
                <origin xyz="0 0 0" rpy="${pi/2} 0 0"/>
                <geometry>
                    <cylinder radius="${wheel_radius}" length="${wheel_thickness}"/>
                </geometry>
            </collision>
            <xacro:cylinder_inertia mass="${wheel_mass}" r="${wheel_radius}" h="${wheel_thickness}"/>
        </link>

        <joint name="${prefix}_wheel_joint" type="continuous">
            <parent link="base_link"/>
            <child link="${prefix}_wheel"/>
            <origin xyz="0 ${y_reflect * (wheel_separation/2)} 0" rpy="0 0 0"/>
            <axis xyz="0 1 0"/>
        </joint>
    </xacro:macro>

    <xacro:wheel prefix="left" y_reflect="1"/>
    <xacro:wheel prefix="right" y_reflect="-1"/>

    <!-- CASTER WHEEL -->
    <joint name="caster_joint" type="fixed">
        <parent link="base_link"/>
        <child link="caster_wheel"/>
        <origin xyz="${caster_offset_x} 0 0"/>
    </joint>

    <link name="caster_wheel">
        <visual>
            <geometry>
                <sphere radius="${caster_radius}"/>
            </geometry>
            <material name="white"/>
        </visual>
        <collision>
            <geometry>
                <sphere radius="${caster_radius}"/>
            </geometry>
        </collision>
        <xacro:sphere_inertia mass="${caster_mass}" r="${caster_radius}"/>
    </link>

    <link name="imu_link">
        <visual>
            <geometry>
                <box size="0.01 0.01 0.01"/>
            </geometry>
            <material name="black"/>
        </visual>
    </link>

    <joint name="imu_joint" type="fixed">
        <parent link="base_link"/>
        <child link="imu_link"/>
        <origin xyz="0.06 0.04 0.03" rpy="0 0 0"/>
    </joint>


    <link name="laser"> 
        <visual>
            <geometry>
                <cylinder radius="${lidar_radius}" length="${lidar_height}"/>
            </geometry>
            <material name="red"/>
        </visual>
        <collision>
            <geometry>
                <cylinder radius="${lidar_radius}" length="${lidar_height}"/>
            </geometry>
        </collision>
        <xacro:cylinder_inertia mass="${lidar_mass}" r="${lidar_radius}" h="${lidar_height}"/>
    </link>

    <joint name="lidar_joint" type="fixed">
        <parent link="base_link"/>
        <child link="laser"/> 
        <origin xyz="${chassis_length/2} 0 ${chassis_height + (lidar_height/2)}" rpy="0 0 3.14159"/>
    </joint>

</robot>
